<mujoco>
  <option gravity="0 0 -9.81"/>
  <worldbody>
    <!-- Frictionless Ramp -->
    <body name="ramp" pos="0 0 0">
      <geom type="plane" size="5 10 0.1" rgba="0.6 0.6 0.6 1" friction="0 0 0" quat="0.5 0.86 0 0"/>
    </body>
    <!-- Ground Surface -->
    <body name="surface" pos="-10 0 -10">
      <geom type="plane" size="30 30 0.1" rgba="0.8 0.8 0.8 1" friction="1 1 1"/>
    </body>
    <!-- Pendulum -->
    <body name="pendulum" pos="-5 0 2">
      <geom type="capsule" fromto="0 0 0 0 0 -1.5" radius="0.05" rgba="0.1 0.8 0.8 1"/>
      <joint name="pendulum_joint" type="hinge" axis="0 1 0"/>
    </body>
    <!-- Sliding Block -->
    <body name="block" pos="5 0 1">
      <geom type="box" size="0.5 0.5 0.5" density="1" rgba="0.8 0.4 0.2 1" friction="0 0 0"/>
      <joint name="block_joint" type="free"/>
    </body>
  </worldbody>
</mujoco>
