<mujoco>
  <option gravity="0 0 -9.81"/>
  <worldbody>
    <body name="ground" pos="0 0 -1">
      <geom type="plane" size="20 20 0.1" rgba="0.9 0.9 0.9 1"/>
    </body>
    <body name="support" pos="0 0 3"/>
    <body name="pendulum_1" pos="-2 0 2.5">
      <geom type="capsule" fromto="0 0 0 0 0 -1.5" size="0.05" rgba="1 0 0 1"/>
      <joint type="hinge" axis="0 1 0" pos="0 0 0"/>
    </body>
    <body name="pendulum_2" pos="0 0 2.5">
      <geom type="capsule" fromto="0 0 0 0 0 -1.0" size="0.05" rgba="0 1 0 1"/>
      <joint type="hinge" axis="0 1 0" pos="0 0 0"/>
    </body>
    <body name="pendulum_3" pos="2 0 2.5">
      <geom type="capsule" fromto="0 0 0 0 0 -0.5" size="0.05" rgba="0 0 1 1"/>
      <joint type="hinge" axis="0 1 0" pos="0 0 0"/>
    </body>
  </worldbody>
</mujoco>
