<mujoco>
  <option gravity="0 0 -9.81"/>
  <worldbody>
    <light diffuse="0.5 0.5 0.5" pos="0 0 5" dir="0 0 -1"/>
    <body name="ground" pos="0 0 -10">
      <geom type="plane" size="50 50 0.1" rgba="0.9 0.9 0.9 1"/>
    </body>
    <body name="spring_block_1" pos="-2 0 2">
      <geom type="box" size="0.3 0.3 0.3" mass="2" rgba="0.6 0.2 1 1"/>
      <joint type="slide" axis="0 0 1" limited="true" range="0 5"/>
    </body>
    <body name="spring_block_2" pos="2 0 2">
      <geom type="box" size="0.3 0.3 0.3" mass="4" rgba="0.1 0.7 0.7 1"/>
      <joint type="slide" axis="0 0 1" limited="true" range="0 5"/>
    </body>
  </worldbody>
</mujoco>
