<mujoco>
  <option gravity="0 0 -9.81"/>
  <worldbody>
    <body name="beam_1" pos="-2 0 0.2">
      <geom type="capsule" fromto="-0.5 0 0 0.5 0 0" size="0.05" rgba="0.7 0.7 0.7 1"/>
      <joint type="hinge" axis="0 0 1"/>
    </body>
    <body name="weight_1" pos="-2.4 0 0.3">
      <geom type="sphere" size="0.1" mass="1" rgba="0.2 0.6 0.2 1"/>
    </body>
    <body name="beam_2" pos="2 0 0.2">
      <geom type="capsule" fromto="-0.5 0 0 0.5 0 0" size="0.05" rgba="0.7 0.7 0.7 1"/>
      <joint type="hinge" axis="0 0 1"/>
    </body>
    <body name="weight_2" pos="2.2 0 0.3">
      <geom type="sphere" size="0.1" mass="1.2" rgba="0.6 0.2 0.2 1"/>
    </body>
  </worldbody>
</mujoco>
