<mujoco>
  <option gravity="0 0 -9.81"/>
  <worldbody>
    <!-- Fixed Support -->
    <body name="support" pos="0 0 2">
      <geom type="sphere" size="0.2" rgba="0.5 0.5 0.5 1"/>
    </body>
    <!-- First Pendulum -->
    <body name="pendulum1" pos="-1 0 2">
      <geom type="capsule" fromto="0 0 0 0 0 -1" radius="0.05" rgba="0.7 0.2 0.2 1"/>
      <joint name="pendulum1_joint" type="hinge" axis="0 1 0"/>
    </body>
    <!-- Second Pendulum attached to the end of the first -->
    <body name="pendulum2" pos="-1 0 1">
      <geom type="capsule" fromto="0 0 0 0 0 -1" radius="0.05" rgba="0.2 0.2 0.7 1"/>
      <joint name="pendulum2_joint" type="hinge" axis="0 1 0"/>
    </body>
  </worldbody>
</mujoco>
