<mujoco>
  <option gravity="0 0 -9.81"/>
  <worldbody>
    <light diffuse="0.5 0.5 0.5" pos="0 0 3" dir="0 0 -1"/>
    <!-- Mass (attached to spring) -->
    <body name="mass" pos="0 0 2">
      <geom type="sphere" size="0.5" density="5" rgba="1 0 0 1"/>
      <joint name="mass_joint" type="slide" axis="0 0 1"/>
    </body>
    <!-- Spring -->
    <body name="spring" pos="0 0 2">
      <joint name="spring_joint" type="hinge" axis="0 0 1" pos="0 0 0"/>
      <geom type="capsule" size="0.1 1.5" rgba="0 1 0 1"/>
    </body>
    <!-- Damping (simulated by friction or damping joint) -->
    <body name="damping" pos="0 0 2">
      <joint name="damping_joint" type="hinge" axis="0 0 1" damping="1.0"/>
    </body>
  </worldbody>
</mujoco>
