<mujoco>
  <option gravity="0 0 -9.81"/>
  <worldbody>
    <light diffuse="0.5 0.5 0.5" pos="0 0 5" dir="0 0 -1"/>
    <body name="ground" pos="0 0 -10">
      <geom type="plane" size="50 50 0.1" rgba="0.85 0.85 0.85 1" friction="1 1 1"/>
    </body>
    <body name="rod_center" pos="-2 0 0.5">
      <geom type="capsule" fromto="-0.5 0 0 0.5 0 0" size="0.1" mass="2" rgba="1 0 0 1"/>
      <joint type="hinge" axis="0 0 1"/>
    </body>
    <body name="rod_end" pos="2 0 0.5">
      <geom type="capsule" fromto="0 0 0 1 0 0" size="0.1" mass="2" rgba="0 0 1 1"/>
      <joint type="hinge" axis="0 0 1"/>
    </body>
  </worldbody>
</mujoco>
