<mujoco>
  <option gravity="0 0 -9.81"/>
  <worldbody>
    <light diffuse="0.5 0.5 0.5" pos="0 0 5" dir="0 0 -1"/>
    <body name="ground" pos="0 0 -10">
      <geom type="plane" size="30 30 0.1" rgba="0.95 0.95 0.95 1"/>
    </body>
    <body name="mass_1" pos="-1 0 2">
      <geom type="box" size="0.3 0.3 0.3" mass="2" rgba="0.4 0.8 1 1"/>
      <joint type="slide" axis="0 0 1"/>
    </body>
    <body name="mass_2" pos="1 0 3">
      <geom type="box" size="0.3 0.3 0.3" mass="4" rgba="1 0.5 0.5 1"/>
      <joint type="slide" axis="0 0 1"/>
    </body>
  </worldbody>
</mujoco>
