<mujoco>
  <option gravity="0 0 -9.81"/>
  <worldbody>
    <body name="ground_plane" pos="0 0 -1">
      <geom type="plane" size="20 20 0.1" rgba="0.9 0.9 0.9 1"/>
    </body>
    <body name="spring_anchor" pos="0 0 0"/>
    <body name="spring_block_1" pos="-1 0 0">
      <geom type="box" size="0.2 0.2 0.2" mass="2" rgba="1 0 0 1"/>
      <joint type="slide" axis="1 0 0"/>
    </body>
    <body name="spring_block_2" pos="1 0 0">
      <geom type="box" size="0.2 0.2 0.2" mass="1" rgba="0 0 1 1"/>
      <joint type="slide" axis="1 0 0"/>
    </body>
    <body name="motion_site" pos="0 0 1"/>
  </worldbody>
  <tendon>
    <spatial name="spring1" width="0.01" springref="0.5" stiffness="50">
      <site site="spring_anchor"/>
      <site site="spring_block_1"/>
    </spatial>
    <spatial name="spring2" width="0.01" springref="0.5" stiffness="100">
      <site site="spring_anchor"/>
      <site site="spring_block_2"/>
    </spatial>
  </tendon>
</mujoco>
