<mujoco>
  <option gravity="0 0 -9.81"/>
  <worldbody>
    <body name="spring_1" pos="-2 0 0.1">
      <geom type="capsule" fromto="0 0 0 0 0 0.4" size="0.05" rgba="0.5 0.5 1 1"/>
    </body>
    <body name="block_1" pos="-2 0 0.6">
      <geom type="box" size="0.1 0.1 0.1" density="1" rgba="0 1 0 1"/>
      <joint type="slide" axis="0 0 1"/>
    </body>
    <body name="spring_2" pos="2 0 0.1">
      <geom type="capsule" fromto="0 0 0 0 0 0.4" size="0.05" rgba="1 0.5 0.5 1"/>
    </body>
    <body name="block_2" pos="2 0 0.6">
      <geom type="box" size="0.1 0.1 0.1" density="1" rgba="0 0 1 1"/>
      <joint type="slide" axis="0 0 1"/>
    </body>
  </worldbody>
</mujoco>
