<mujoco>
  <option gravity="0 0 -9.81"/>
  <worldbody>
    <body name="ground" pos="0 0 -1">
      <geom type="plane" size="30 30 0.1" rgba="0.7 0.7 0.7 1"/>
    </body>
    <body name="platform" pos="0 0 0.1">
      <geom type="cylinder" size="0.6 0.05" density="0.5" rgba="0.2 0.2 1 1"/>
      <joint type="hinge" axis="0 0 1" name="rotation"/>
    </body>
    <body name="mass_1" pos="0.4 0 0.2">
      <geom type="sphere" size="0.05" density="1" rgba="1 0 0 1"/>
    </body>
    <body name="mass_2" pos="-0.4 0 0.2">
      <geom type="sphere" size="0.05" density="1" rgba="0 1 0 1"/>
    </body>
  </worldbody>
</mujoco>
