<mujoco>
  <option gravity="0 0 -9.81"/>
  <worldbody>
    <!-- Ground -->
    <body name="ground" pos="0 0 -10">
      <geom type="plane" size="30 30 0.1" rgba="0.9 0.9 0.9 1"/>
    </body>
    <!-- Plank -->
    <body name="plank" pos="0 0 0.5">
      <geom type="box" size="5 0.2 0.1" density="0.5" rgba="0.6 0.4 0.2 1"/>
      <joint name="plank_joint" type="hinge" axis="0 1 0"/>
    </body>
    <!-- Mass Left -->
    <body name="mass_left" pos="-3 0 1">
      <geom type="sphere" size="0.3" density="2" rgba="1 0 0 1"/>
    </body>
    <!-- Mass Right -->
    <body name="mass_right" pos="3 0 1">
      <geom type="sphere" size="0.3" density="1" rgba="0 0 1 1"/>
    </body>
    <!-- Movable Mass -->
    <body name="mass_to_place" pos="0 0 2">
      <geom type="sphere" size="0.3" density="1.5" rgba="0 1 0 1"/>
    </body>
  </worldbody>
</mujoco>
