<mujoco>
  <option gravity="0 0 -9.81"/>
  <worldbody>
    <!-- Spring -->
    <body name="spring" pos="0 0 0">
      <geom type="cylinder" size="0.1 1" density="5" rgba="1 0 0 1"/>
      <joint name="spring_joint" type="hinge" axis="0 0 1"/>
    </body>
    
    <!-- Block -->
    <body name="block" pos="0 0 1">
      <geom type="box" size="0.5 0.25 0.25" density="2" rgba="0 0 1 1"/>
      <joint name="block_joint" type="free"/>
    </body>
    
    <!-- Surface -->
    <body name="surface" pos="0 0 -10">
      <geom type="plane" size="30 30 0.1" rgba="0.7 0.7 0.7 1" friction="0.5 0.5 0.5"/>
    </body>
  </worldbody>
</mujoco>
